This test is currently not working at expected: it does not include proper
backtrace locations for the exception raised in the ocaml script file. See
'Called from unknown location' in
toplevel_script_backtrace.ocaml.reference
Exception: Failure "test".
Raised at Stdlib.failwith in file "stdlib.ml", line 29, characters 17-33
Called from unknown location
Called from Toploop.load_lambda in file "toplevel/toploop.ml", line 212, characters 17-27
